Workbook

Sheet Input Operativo
A1: COSCO SHIPPING PORTS CHANCAY PERU S.A. (CSPCP)
A2: FICHA DE OBSERVACION OPERATIVA POR TURNO · OPM
A4: Escala 1 a 5. Marque con X. La columna OBJ indica a que objetivo aporta cada tarea. Lo no realizado: N/A.
A5: Fecha | F5: Turno
A6: Nave / Operacion | F6: Tipo carga
A7: OPM (codigo) | F7: Nombre
A8: Supervisor de operaciones
A10: OBJ | B10: ACTIVIDAD | C10: 1 Insatisf. | D10: 2 Regular | E10: 3 Aceptable | F10: 4 Bueno | G10: 5 Excelente | H10: N/A | I10: Pts
A11: TRANSVERSAL (todo turno)
A12: O4 | B12: Inspeccion preoperacional de equipos y aparejos | I12: =IF(COUNTIF(C12:G12,"X")=0,"",1*(C12="X")+2*(D12="X")+3*(E12="X")+4*(F12="X")+5*(G12="X"))
A13: O4 | B13: Preparacion y senalizacion del area | I13: =IF(COUNTIF(C13:G13,"X")=0,"",1*(C13="X")+2*(D13="X")+3*(E13="X")+4*(F13="X")+5*(G13="X"))
A14: O1 | B14: Uso de EPP | I14: =IF(COUNTIF(C14:G14,"X")=0,"",1*(C14="X")+2*(D14="X")+3*(E14="X")+4*(F14="X")+5*(G14="X"))
A15: O4 | B15: Orden y limpieza | I15: =IF(COUNTIF(C15:G15,"X")=0,"",1*(C15="X")+2*(D15="X")+3*(E15="X")+4*(F15="X")+5*(G15="X"))
A16: AMARRE (si participo)
A17: O2 | B17: Amarre / desamarre | I17: =IF(COUNTIF(C17:G17,"X")=0,"",1*(C17="X")+2*(D17="X")+3*(E17="X")+4*(F17="X")+5*(G17="X"))
A18: O2 | B18: Uso de shore tension | I18: =IF(COUNTIF(C18:G18,"X")=0,"",1*(C18="X")+2*(D18="X")+3*(E18="X")+4*(F18="X")+5*(G18="X"))
A19: CONTENEDORES
A20: O2 | B20: Senalizacion a grua / portalon | I20: =IF(COUNTIF(C20:G20,"X")=0,"",1*(C20="X")+2*(D20="X")+3*(E20="X")+4*(F20="X")+5*(G20="X"))
A21: O2 | B21: Trincado / destrincado | I21: =IF(COUNTIF(C21:G21,"X")=0,"",1*(C21="X")+2*(D21="X")+3*(E21="X")+4*(F21="X")+5*(G21="X"))
A22: O2 | B22: Pin station (retiro y colocacion de pinas) | I22: =IF(COUNTIF(C22:G22,"X")=0,"",1*(C22="X")+2*(D22="X")+3*(E22="X")+4*(F22="X")+5*(G22="X"))
A23: O2 | B23: Uso de PDA | I23: =IF(COUNTIF(C23:G23,"X")=0,"",1*(C23="X")+2*(D23="X")+3*(E23="X")+4*(F23="X")+5*(G23="X"))
A24: O2 | B24: Lectura de planos | I24: =IF(COUNTIF(C24:G24,"X")=0,"",1*(C24="X")+2*(D24="X")+3*(E24="X")+4*(F24="X")+5*(G24="X"))
A25: O2 | B25: Reefer (conexion / monitoreo) | I25: =IF(COUNTIF(C25:G25,"X")=0,"",1*(C25="X")+2*(D25="X")+3*(E25="X")+4*(F25="X")+5*(G25="X"))
A26: GRANEL SOLIDO
A27: O2 | B27: Dominio de hopper | I27: =IF(COUNTIF(C27:G27,"X")=0,"",1*(C27="X")+2*(D27="X")+3*(E27="X")+4*(F27="X")+5*(G27="X"))
A28: O2 | B28: Trimming / nivelacion de carga | I28: =IF(COUNTIF(C28:G28,"X")=0,"",1*(C28="X")+2*(D28="X")+3*(E28="X")+4*(F28="X")+5*(G28="X"))
A29: O2 | B29: Comunicacion con operadores | I29: =IF(COUNTIF(C29:G29,"X")=0,"",1*(C29="X")+2*(D29="X")+3*(E29="X")+4*(F29="X")+5*(G29="X"))
A30: O2 | B30: Limpieza de bodegas | I30: =IF(COUNTIF(C30:G30,"X")=0,"",1*(C30="X")+2*(D30="X")+3*(E30="X")+4*(F30="X")+5*(G30="X"))
A31: O1 | B31: Control de material de izaje | I31: =IF(COUNTIF(C31:G31,"X")=0,"",1*(C31="X")+2*(D31="X")+3*(E31="X")+4*(F31="X")+5*(G31="X"))
A32: CARGA FRACCIONADA
A33: O2 | B33: Aparejamiento (rigging) | I33: =IF(COUNTIF(C33:G33,"X")=0,"",1*(C33="X")+2*(D33="X")+3*(E33="X")+4*(F33="X")+5*(G33="X"))
A34: O1 | B34: Revision de materiales de izaje + alerta de deterioro | I34: =IF(COUNTIF(C34:G34,"X")=0,"",1*(C34="X")+2*(D34="X")+3*(E34="X")+4*(F34="X")+5*(G34="X"))
A35: O2 | B35: Ejecucion del plan de izaje | I35: =IF(COUNTIF(C35:G35,"X")=0,"",1*(C35="X")+2*(D35="X")+3*(E35="X")+4*(F35="X")+5*(G35="X"))
A36: O2 | B36: Senalero / rigger | I36: =IF(COUNTIF(C36:G36,"X")=0,"",1*(C36="X")+2*(D36="X")+3*(E36="X")+4*(F36="X")+5*(G36="X"))
A37: O2 | B37: Aseguramiento de material de izaje | I37: =IF(COUNTIF(C37:G37,"X")=0,"",1*(C37="X")+2*(D37="X")+3*(E37="X")+4*(F37="X")+5*(G37="X"))
A38: BIG BAGS
A39: O2 | B39: Eslingado / enganche de big bags con seguridad | I39: =IF(COUNTIF(C39:G39,"X")=0,"",1*(C39="X")+2*(D39="X")+3*(E39="X")+4*(F39="X")+5*(G39="X"))
A40: O2 | B40: Comunicacion con montacarguista (big bags) | I40: =IF(COUNTIF(C40:G40,"X")=0,"",1*(C40="X")+2*(D40="X")+3*(E40="X")+4*(F40="X")+5*(G40="X"))
A41: O1 | B41: Revision de materiales de izaje | I41: =IF(COUNTIF(C41:G41,"X")=0,"",1*(C41="X")+2*(D41="X")+3*(E41="X")+4*(F41="X")+5*(G41="X"))
A42: O1 | B42: Seguridad en maniobras | I42: =IF(COUNTIF(C42:G42,"X")=0,"",1*(C42="X")+2*(D42="X")+3*(E42="X")+4*(F42="X")+5*(G42="X"))
...

Sheet Tabulacion y Minimos
A1: COSCO SHIPPING PORTS CHANCAY PERU S.A. (CSPCP)
A2: TABULACION DE ESCALAS Y PUNTAJES MINIMOS ESPERADOS
A4: El supervisor registra en escala 1-5. Para la evaluacion de desempeno, el promedio 1-5 se convierte a los 3 niveles de CSPCP, manteniendo la alineacion con el Modelo de Liderazgo Institucional.
A6: A. ESCALA DE REGISTRO OPERATIVO (1 a 5)
A7: Puntaje | B7: Calificacion | C7: Descripcion
A8: 1 | B8: Insatisfactorio | C8: No ejecuta segun el estandar; genera riesgo o retrabajo.
A9: 2 | B9: Regular | C9: Ejecuta con errores frecuentes; requiere supervision constante.
A10: 3 | B10: Aceptable | C10: Ejecuta conforme al estandar minimo, de forma segura y autonoma.
A11: 4 | B11: Bueno | C11: Ejecuta con solvencia y sin observaciones; buen ritmo y calidad.
A12: 5 | B12: Excelente | C12: Ejecuta con excelencia; resuelve imprevistos y apoya a otros.
A14: B. CONVERSION AL MODELO CSPCP (3 niveles)
A15: Promedio 1-5 | B15: Nivel CSPCP | D15: Significado
A16: 4.5 o mas | B16: Sobre las Expectativas | D16: Desempeno consistente entre Bueno y Excelente.
A17: 3.0 a 4.49 | B17: Cumple las Expectativas | D17: Alcanza o supera el estandar minimo esperado.
A18: menor a 3.0 | B18: Por Debajo de las Expectativas | D18: No alcanza el estandar minimo; se documenta como brecha.
A20: C. PUNTAJE MINIMO ESPERADO POR TIPO DE CARGA
A21: Estandar unico para todos los bloques: el promedio del bloque debe alcanzar el minimo esperado.
A22: Bloque / tipo de carga | B22: N. actividades | C22: Minimo esperado | D22: Equivale a
A23: Transversal (todo turno) | B23: 4 | C23: =Parametros!$B$23 -> 3 | D23: Aceptable (3)
A24: Amarre (si participo) | B24: 2 | C24: =Parametros!$B$23 -> 3 | D24: Aceptable (3)
A25: Contenedores | B25: 6 | C25: =Parametros!$B$23 -> 3 | D25: Aceptable (3)
A26: Granel solido | B26: 5 | C26: =Parametros!$B$23 -> 3 | D26: Aceptable (3)
A27: Carga fraccionada | B27: 5 | C27: =Parametros!$B$23 -> 3 | D27: Aceptable (3)
A28: Big bags | B28: 4 | C28: =Parametros!$B$23 -> 3 | D28: Aceptable (3)
A29: Productividad | B29: 1 | C29: =Parametros!$B$23 -> 3 | D29: Aceptable (3)
A30: Lectura: si el promedio de un bloque queda por debajo de 3.0, ese tipo de carga esta bajo el estandar y debe documentarse como brecha en la evaluacion (posible PIP).

Sheet Evaluacion de Desempeno
A1: COSCO SHIPPING PORTS CHANCAY PERU S.A. (CSPCP)
A2: EVALUACION DE DESEMPENO · OPM
A5: OPM (codigo) | C5: Nombre
A6: Categoria / puesto | C6: Ciclo
A7: Evaluador (jefe directo) | C7: Fecha
A9: A. LOGRO DE OBJETIVOS (70%)
A10: Ingrese el promedio 1-5 del ciclo (viene de los 'Promedios por objetivo' de las fichas de turno).
A11: Objetivo | B11: Peso | C11: Promedio 1-5 | D11: Nivel CSPCP
A12: O1 · Seguridad y cumplimiento | B12: =Parametros!$B$4 -> 0.4 | D12: =IF(C12="","",IF(C12>=Parametros!$B$11,"Sobre",IF(C12>=Parametros!$B$12,"Cumple","Por Debajo")))
A13: O2 · Ejecucion tecnica por tipo de carga | B13: =Parametros!$B$5 -> 0.3 | D13: =IF(C13="","",IF(C13>=Parametros!$B$11,"Sobre",IF(C13>=Parametros!$B$12,"Cumple","Por Debajo")))
A14: O3 · Productividad operacional | B14: =Parametros!$B$6 -> 0.15 | D14: =IF(C14="","",IF(C14>=Parametros!$B$11,"Sobre",IF(C14>=Parametros!$B$12,"Cumple","Por Debajo")))
A15: O4 · Cuidado de carga y equipos | B15: =Parametros!$B$7 -> 0.15 | D15: =IF(C15="","",IF(C15>=Parametros!$B$11,"Sobre",IF(C15>=Parametros!$B$12,"Cumple","Por Debajo")))
A16: PUNTAJE OBJETIVOS (70%) · promedio 1-5 | C16: =IFERROR((IF(C12="",0,B12*C12)+IF(C13="",0,B13*C13)+IF(C14="",0,B14*C14)+IF(C15="",0,B15*C15))/(IF(C12="",0,B12)+IF(C13="",0,B13)+IF(C14="",0,B14)+IF(C15="",0,B15)),"") | D16: =IF(C16="","",IF(C16>=Parametros!$B$11,"Sobre",IF(C16>=Parametros!$B$12,"Cumple","Por Debajo")))
A18: B. CONDUCTAS CORPORATIVAS (30%) · Modelo de Liderazgo Institucional CSPCP
A19: Se califican en 3 niveles y se convierten a la escala 1-5 (Por Debajo=1, Cumple=3, Sobre=5).
A20: Comportamiento organizacional | C20: Calificacion
A21: Comunicacion
A22: Adaptabilidad
A23: Trabajo en equipo
A24: Iniciativa e innovacion
A25: Respeto
A26: Orientacion a la seguridad
A27: Orientacion a resultados
A28: PUNTAJE CONDUCTAS (30%) · escala 1-5 | C28: =IFERROR((SUMPRODUCT((C21:C27="Sobre")*5+(C21:C27="Cumple")*3+(C21:C27="Por Debajo")*1))/(SUMPRODUCT((C21:C27="Sobre")+(C21:C27="Cumple")+(C21:C27="Por Debajo"))),"")
A29: C. RESULTADO FINAL
A30: Nivel objetivos (70%) | C30: =D16
A31: Nivel conductas (30%) | C31: =IF(C28="","",IF(C28>=Parametros!$B$11,"Sobre",IF(C28>=Parametros!$B$12,"Cumple","Por Debajo")))
A32: Score combinado (70/30, escala 1-5) | C32: =IF(OR(C16="",C28=""),"",Parametros!$B$19*C16+Parametros!$B$20*C28)
A33: NIVEL FINAL | C33: =IF(C32="","",IF(AND((IF(C32>=Parametros!$B$11,"Sobre",IF(C32>=Parametros!$B$12,"Cumple","Por Debajo")))="Sobre",C31="Por Debajo"),"Cumple",IF(C32>=Parametros!$B$11,"Sobre",IF(C32>=Parametros!$B$12,"Cumple","Por Debajo"))))
A34: Regla CSPCP: un 'Por Debajo' en conductas impide un 'Sobre' final.
A35: D. EVIDENCIAS Y COMENTARIOS
A38: E. PLAN DE DESARROLLO / PIP
A39: PIP activado (Si/No): | C39: Acciones / plazos:
A41: F. FIRMAS
A43: ____________________ | C43: ____________________
A44: OPM | C44: Jefe directo
A46: ____________________
A47: Recursos Humanos

Sheet Parametros
A1: PARAMETROS
A3: Pesos de objetivos (suman 100%)
A4: Peso Obj 1 - Seguridad | B4: 0.4
A5: Peso Obj 2 - Ejecucion tecnica | B5: 0.3
A6: Peso Obj 3 - Productividad | B6: 0.15
A7: Peso Obj 4 - Cuidado | B7: 0.15
A8: Suma | B8: =SUM(B4:B7) -> 1
A10: Cortes escala 1-5 -> nivel CSPCP
A11: Umbral 'Sobre' (>=) | B11: 4.5
A12: Umbral 'Cumple' (>=) | B12: 3
A14: Conversion de conductas a escala 1-5
A15: Sobre = 5 | Cumple = 3 | Por Debajo = 1
A18: Dimensiones CSPCP
A19: Peso Objetivos | B19: 0.7
A20: Peso Conductas | B20: 0.3
A22: Estandar
A23: Puntaje minimo esperado (1-5) | B23: 3
A24: Tope por evento de seguridad (O1 y O3) | B24: 2.5
A26: Control trimestral
A27: Piso minimo de fichas por OPM | B27: 8
A28: % minimo de turnos muestreados | B28: 0.2
A29: % de OPM a registrar por turno (supervisor) | B29: 0.25
A30: Cobertura minima por tipo de carga (fichas) | B30: 2
A31: Supervisores distintos minimos | B31: 3

Sheet Registro de Fichas
A1: COSCO SHIPPING PORTS CHANCAY PERU S.A. (CSPCP)
A2: REGISTRO DE FICHAS DE OBSERVACION · una fila por ficha entregada
A4: Digite aqui el resultado de cada ficha de observacion. Los promedios O1-O4 se copian del bloque 'PROMEDIOS POR OBJETIVO' de la ficha del turno. La hoja 'Control Trimestral' consolida sola.
A6: Fecha | B6: Turno | C6: Team | D6: OPM (codigo) | E6: OPM nombre | F6: Supervisor | G6: O1 Seguridad | H6: O2 Ejecucion | I6: O3 Product. | J6: O4 Cuidado | K6: Tipo carga | L6: Evento seg. | M6: aux
A7: 05/07/2026 | B7: Dia | C7: A | D7: OPM-001 | E7: Juan Perez (EJEMPLO) | F7: C. Rodriguez | G7: 5 | H7: 4 | I7: 4 | J7: 3.67 | K7: Contenedores | L7: No | M7: =IF(OR($D7="",$F7=""),"",IF(COUNTIFS($D$7:$D7,$D7,$F$7:$F7,$F7)=1,1,0)) -> 1
M8: =IF(OR($D8="",$F8=""),"",IF(COUNTIFS($D$7:$D8,$D8,$F$7:$F8,$F8)=1,1,0))
M9: =IF(OR($D9="",$F9=""),"",IF(COUNTIFS($D$7:$D9,$D9,$F$7:$F9,$F9)=1,1,0))
M10: =IF(OR($D10="",$F10=""),"",IF(COUNTIFS($D$7:$D10,$D10,$F$7:$F10,$F10)=1,1,0))
M11: =IF(OR($D11="",$F11=""),"",IF(COUNTIFS($D$7:$D11,$D11,$F$7:$F11,$F11)=1,1,0))
M12: =IF(OR($D12="",$F12=""),"",IF(COUNTIFS($D$7:$D12,$D12,$F$7:$F12,$F12)=1,1,0))
M13: =IF(OR($D13="",$F13=""),"",IF(COUNTIFS($D$7:$D13,$D13,$F$7:$F13,$F13)=1,1,0))
M14: =IF(OR($D14="",$F14=""),"",IF(COUNTIFS($D$7:$D14,$D14,$F$7:$F14,$F14)=1,1,0))
M15: =IF(OR($D15="",$F15=""),"",IF(COUNTIFS($D$7:$D15,$D15,$F$7:$F15,$F15)=1,1,0))
M16: =IF(OR($D16="",$F16=""),"",IF(COUNTIFS($D$7:$D16,$D16,$F$7:$F16,$F16)=1,1,0))
M17: =IF(OR($D17="",$F17=""),"",IF(COUNTIFS($D$7:$D17,$D17,$F$7:$F17,$F17)=1,1,0))
M18: =IF(OR($D18="",$F18=""),"",IF(COUNTIFS($D$7:$D18,$D18,$F$7:$F18,$F18)=1,1,0))
M19: =IF(OR($D19="",$F19=""),"",IF(COUNTIFS($D$7:$D19,$D19,$F$7:$F19,$F19)=1,1,0))
... M1200: =IF(OR($D1200="",$F1200=""),"",IF(COUNTIFS($D$7:$D1200,$D1200,$F$7:$F1200,$F1200)=1,1,0))

Sheet Control Trimestral
A1: COSCO SHIPPING PORTS CHANCAY PERU S.A. (CSPCP)
A2: CONTROL Y CONSOLIDACION TRIMESTRAL · OPM
A4: Liste los codigos de OPM en la columna A. Todo lo demas se calcula solo desde 'Registro de Fichas'. Los promedios O1-O4 son los que se trasladan a la ficha de Evaluacion de Desempeno.
A5: IDENTIFICACION | C5: VOLUMEN | E5: PROMEDIOS DEL TRIMESTRE (1-5) | I5: VALIDEZ | K5: COBERTURA POR TIPO DE CARGA | O5: RESULTADO
A6: OPM codigo | B6: OPM nombre | C6: Fichas | D6: Turnos trab. | E6: O1 | F6: O2 | G6: O3 | H6: O4 | I6: Piso 8 | J6: Superv. dist. | K6: Conten. | L6: Granel | M6: Fracc. | N6: Big bags | O6: Eventos seg. | P6: ESTADO
A7: OPM-001 | B7: =IFERROR(INDEX('Registro de Fichas'!$E$7:$E$1200,MATCH($A7,'Registro de Fichas'!$D$7:$D$1200,0)),"") -> Juan Perez (EJEMPLO) | C7: =COUNTIF('Registro de Fichas'!$D$7:$D$1200,$A7) -> 1 | E7: =IFERROR(AVERAGEIF('Registro de Fichas'!$D$7:$D$1200,$A7,'Registro de Fichas'!$G$7:$G$1200),"") -> 5 | F7: =IFERROR(AVERAGEIF('Registro de Fichas'!$D$7:$D$1200,$A7,'Registro de Fichas'!$H$7:$H$1200),"") -> 4 | G7: =IFERROR(AVERAGEIF('Registro de Fichas'!$D$7:$D$1200,$A7,'Registro de Fichas'!$I$7:$I$1200),"") -> 4 | H7: =IFERROR(AVERAGEIF('Registro de Fichas'!$D$7:$D$1200,$A7,'Registro de Fichas'!$J$7:$J$1200),"") -> 3.67 | I7: =IF($C7=0,"",IF($C7>=Parametros!$B$27,"OK","FALTAN "&(Parametros!$B$27-$C7))) -> FALTAN 7 | J7: =IF($C7=0,"",SUMIF('Registro de Fichas'!$D$7:$D$1200,$A7,'Registro de Fichas'!$M$7:$M$1200)) -> 1 | K7: =COUNTIFS('Registro de Fichas'!$D$7:$D$1200,$A7,'Registro de Fichas'!$K$7:$K$1200,"Contenedores") -> 1 | L7: =COUNTIFS('Registro de Fichas'!$D$7:$D$1200,$A7,'Registro de Fichas'!$K$7:$K$1200,"Granel solido") -> 0 | M7: =COUNTIFS('Registro de Fichas'!$D$7:$D$1200,$A7,'Registro de Fichas'!$K$7:$K$1200,"Carga fraccionada") -> 0 | N7: =COUNTIFS('Registro de Fichas'!$D$7:$D$1200,$A7,'Registro de Fichas'!$K$7:$K$1200,"Big bags") -> 0 | O7: =COUNTIFS('Registro de Fichas'!$D$7:$D$1200,$A7,'Registro de Fichas'!$L$7:$L$1200,"Si") -> 0 | P7: =IF($C7=0,"",IF($C7<Parametros!$B$27,"EVIDENCIA INSUFICIENTE",IF(AND($D7<>"",$C7<$D7*Parametros!$B$28),"BAJO % MUESTREO",IF($J7<Parametros!$B$31,"POCOS EVALUADORES","VALIDA")))) -> EVIDENCIA INSUFICIENTE
B8: =IFERROR(INDEX('Registro de Fichas'!$E$7:$E$1200,MATCH($A8,'Registro de Fichas'!$D$7:$D$1200,0)),"") | C8: =COUNTIF('Registro de Fichas'!$D$7:$D$1200,$A8) -> 0 | E8: =IFERROR(AVERAGEIF('Registro de Fichas'!$D$7:$D$1200,$A8,'Registro de Fichas'!$G$7:$G$1200),"") | F8: =IFERROR(AVERAGEIF('Registro de Fichas'!$D$7:$D$1200,$A8,'Registro de Fichas'!$H$7:$H$1200),"") | G8: =IFERROR(AVERAGEIF('Registro de Fichas'!$D$7:$D$1200,$A8,'Registro de Fichas'!$I$7:$I$1200),"") | H8: =IFERROR(AVERAGEIF('Registro de Fichas'!$D$7:$D$1200,$A8,'Registro de Fichas'!$J$7:$J$1200),"") | I8: =IF($C8=0,"",IF($C8>=Parametros!$B$27,"OK","FALTAN "&(Parametros!$B$27-$C8))) | J8: =IF($C8=0,"",SUMIF('Registro de Fichas'!$D$7:$D$1200,$A8,'Registro de Fichas'!$M$7:$M$1200)) | K8: =COUNTIFS('Registro de Fichas'!$D$7:$D$1200,$A8,'Registro de Fichas'!$K$7:$K$1200,"Contenedores") -> 0 | L8: =COUNTIFS('Registro de Fichas'!$D$7:$D$1200,$A8,'Registro de Fichas'!$K$7:$K$1200,"Granel solido") -> 0 | M8: =COUNTIFS('Registro de Fichas'!$D$7:$D$1200,$A8,'Registro de Fichas'!$K$7:$K$1200,"Carga fraccionada") -> 0 | N8: =COUNTIFS('Registro de Fichas'!$D$7:$D$1200,$A8,'Registro de Fichas'!$K$7:$K$1200,"Big bags") -> 0 | O8: =COUNTIFS('Registro de Fichas'!$D$7:$D$1200,$A8,'Registro de Fichas'!$L$7:$L$1200,"Si") -> 0 | P8: =IF($C8=0,"",IF($C8<Parametros!$B$27,"EVIDENCIA INSUFICIENTE",IF(AND($D8<>"",$C8<$D8*Parametros!$B$28),"BAJO % MUESTREO",IF($J8<Parametros!$B$31,"POCOS EVALUADORES","VALIDA"))))
B9: =IFERROR(INDEX('Registro de Fichas'!$E$7:$E$1200,MATCH($A9,'Registro de Fichas'!$D$7:$D$1200,0)),"") | C9: =COUNTIF('Registro de Fichas'!$D$7:$D$1200,$A9) -> 0 | E9: =IFERROR(AVERAGEIF('Registro de Fichas'!$D$7:$D$1200,$A9,'Registro de Fichas'!$G$7:$G$1200),"") | F9: =IFERROR(AVERAGEIF('Registro de Fichas'!$D$7:$D$1200,$A9,'Registro de Fichas'!$H$7:$H$1200),"") | G9: =IFERROR(AVERAGEIF('Registro de Fichas'!$D$7:$D$1200,$A9,'Registro de Fichas'!$I$7:$I$1200),"") | H9: =IFERROR(AVERAGEIF('Registro de Fichas'!$D$7:$D$1200,$A9,'Registro de Fichas'!$J$7:$J$1200),"") | I9: =IF($C9=0,"",IF($C9>=Parametros!$B$27,"OK","FALTAN "&(Parametros!$B$27-$C9))) | J9: =IF($C9=0,"",SUMIF('Registro de Fichas'!$D$7:$D$1200,$A9,'Registro de Fichas'!$M$7:$M$1200)) | K9: =COUNTIFS('Registro de Fichas'!$D$7:$D$1200,$A9,'Registro de Fichas'!$K$7:$K$1200,"Contenedores") -> 0 | L9: =COUNTIFS('Registro de Fichas'!$D$7:$D$1200,$A9,'Registro de Fichas'!$K$7:$K$1200,"Granel solido") -> 0 | M9: =COUNTIFS('Registro de Fichas'!$D$7:$D$1200,$A9,'Registro de Fichas'!$K$7:$K$1200,"Carga fraccionada") -> 0 | N9: =COUNTIFS('Registro de Fichas'!$D$7:$D$1200,$A9,'Registro de Fichas'!$K$7:$K$1200,"Big bags") -> 0 | O9: =COUNTIFS('Registro de Fichas'!$D$7:$D$1200,$A9,'Registro de Fichas'!$L$7:$L$1200,"Si") -> 0 | P9: =IF($C9=0,"",IF($C9<Parametros!$B$27,"EVIDENCIA INSUFICIENTE",IF(AND($D9<>"",$C9<$D9*Parametros!$B$28),"BAJO % MUESTREO",IF($J9<Parametros!$B$31,"POCOS EVALUADORES","VALIDA"))))
B10: =IFERROR(INDEX('Registro de Fichas'!$E$7:$E$1200,MATCH($A10,'Registro de Fichas'!$D$7:$D$1200,0)),"") | C10: =COUNTIF('Registro de Fichas'!$D$7:$D$1200,$A10) -> 0 | E10: =IFERROR(AVERAGEIF('Registro de Fichas'!$D$7:$D$1200,$A10,'Registro de Fichas'!$G$7:$G$1200),"") | F10: =IFERROR(AVERAGEIF('Registro de Fichas'!$D$7:$D$1200,$A10,'Registro de Fichas'!$H$7:$H$1200),"") | G10: =IFERROR(AVERAGEIF('Registro de Fichas'!$D$7:$D$1200,$A10,'Registro de Fichas'!$I$7:$I$1200),"") | H10: =IFERROR(AVERAGEIF('Registro de Fichas'!$D$7:$D$1200,$A10,'Registro de Fichas'!$J$7:$J$1200),"") | I10: =IF($C10=0,"",IF($C10>=Parametros!$B$27,"OK","FALTAN "&(Parametros!$B$27-$C10))) | J10: =IF($C10=0,"",SUMIF('Registro de Fichas'!$D$7:$D$1200,$A10,'Registro de Fichas'!$M$7:$M$1200)) | K10: =COUNTIFS('Registro de Fichas'!$D$7:$D$1200,$A10,'Registro de Fichas'!$K$7:$K$1200,"Contenedores") -> 0 | L10: =COUNTIFS('Registro de Fichas'!$D$7:$D$1200,$A10,'Registro de Fichas'!$K$7:$K$1200,"Granel solido") -> 0 | M10: =COUNTIFS('Registro de Fichas'!$D$7:$D$1200,$A10,'Registro de Fichas'!$K$7:$K$1200,"Carga fraccionada") -> 0 | N10: =COUNTIFS('Registro de Fichas'!$D$7:$D$1200,$A10,'Registro de Fichas'!$K$7:$K$1200,"Big bags") -> 0 | O10: =COUNTIFS('Registro de Fichas'!$D$7:$D$1200,$A10,'Registro de Fichas'!$L$7:$L$1200,"Si") -> 0 | P10: =IF($C10=0,"",IF($C10<Parametros!$B$27,"EVIDENCIA INSUFICIENTE",IF(AND($D10<>"",$C10<$D10*Parametros!$B$28),"BAJO % MUESTREO",IF($J10<Parametros!$B$31,"POCOS EVALUADORES","VALIDA"))))
B11: =IFERROR(INDEX('Registro de Fichas'!$E$7:$E$1200,MATCH($A11,'Registro de Fichas'!$D$7:$D$1200,0)),"") | C11: =COUNTIF('Registro de Fichas'!$D$7:$D$1200,$A11) -> 0 | E11: =IFERROR(AVERAGEIF('Registro de Fichas'!$D$7:$D$1200,$A11,'Registro de Fichas'!$G$7:$G$1200),"") | F11: =IFERROR(AVERAGEIF('Registro de Fichas'!$D$7:$D$1200,$A11,'Registro de Fichas'!$H$7:$H$1200),"") | G11: =IFERROR(AVERAGEIF('Registro de Fichas'!$D$7:$D$1200,$A11,'Registro de Fichas'!$I$7:$I$1200),"") | H11: =IFERROR(AVERAGEIF('Registro de Fichas'!$D$7:$D$1200,$A11,'Registro de Fichas'!$J$7:$J$1200),"") | I11: =IF($C11=0,"",IF($C11>=Parametros!$B$27,"OK","FALTAN "&(Parametros!$B$27-$C11))) | J11: =IF($C11=0,"",SUMIF('Registro de Fichas'!$D$7:$D$1200,$A11,'Registro de Fichas'!$M$7:$M$1200)) | K11: =COUNTIFS('Registro de Fichas'!$D$7:$D$1200,$A11,'Registro de Fichas'!$K$7:$K$1200,"Contenedores") -> 0 | L11: =COUNTIFS('Registro de Fichas'!$D$7:$D$1200,$A11,'Registro de Fichas'!$K$7:$K$1200,"Granel solido") -> 0 | M11: =COUNTIFS('Registro de Fichas'!$D$7:$D$1200,$A11,'Registro de Fichas'!$K$7:$K$1200,"Carga fraccionada") -> 0 | N11: =COUNTIFS('Registro de Fichas'!$D$7:$D$1200,$A11,'Registro de Fichas'!$K$7:$K$1200,"Big bags") -> 0 | O11: =COUNTIFS('Registro de Fichas'!$D$7:$D$1200,$A11,'Registro de Fichas'!$L$7:$L$1200,"Si") -> 0 | P11: =IF($C11=0,"",IF($C11<Parametros!$B$27,"EVIDENCIA INSUFICIENTE",IF(AND($D11<>"",$C11<$D11*Parametros!$B$28),"BAJO % MUESTREO",IF($J11<Parametros!$B$31,"POCOS EVALUADORES","VALIDA"))))
B12: =IFERROR(INDEX('Registro de Fichas'!$E$7:$E$1200,MATCH($A12,'Registro de Fichas'!$D$7:$D$1200,0)),"") | C12: =COUNTIF('Registro de Fichas'!$D$7:$D$1200,$A12) -> 0 | E12: =IFERROR(AVERAGEIF('Registro de Fichas'!$D$7:$D$1200,$A12,'Registro de Fichas'!$G$7:$G$1200),"") | F12: =IFERROR(AVERAGEIF('Registro de Fichas'!$D$7:$D$1200,$A12,'Registro de Fichas'!$H$7:$H$1200),"") | G12: =IFERROR(AVERAGEIF('Registro de Fichas'!$D$7:$D$1200,$A12,'Registro de Fichas'!$I$7:$I$1200),"") | H12: =IFERROR(AVERAGEIF('Registro de Fichas'!$D$7:$D$1200,$A12,'Registro de Fichas'!$J$7:$J$1200),"") | I12: =IF($C12=0,"",IF($C12>=Parametros!$B$27,"OK","FALTAN "&(Parametros!$B$27-$C12))) | J12: =IF($C12=0,"",SUMIF('Registro de Fichas'!$D$7:$D$1200,$A12,'Registro de Fichas'!$M$7:$M$1200)) | K12: =COUNTIFS('Registro de Fichas'!$D$7:$D$1200,$A12,'Registro de Fichas'!$K$7:$K$1200,"Contenedores") -> 0 | L12: =COUNTIFS('Registro de Fichas'!$D$7:$D$1200,$A12,'Registro de Fichas'!$K$7:$K$1200,"Granel solido") -> 0 | M12: =COUNTIFS('Registro de Fichas'!$D$7:$D$1200,$A12,'Registro de Fichas'!$K$7:$K$1200,"Carga fraccionada") -> 0 | N12: =COUNTIFS('Registro de Fichas'!$D$7:$D$1200,$A12,'Registro de Fichas'!$K$7:$K$1200,"Big bags") -> 0 | O12: =COUNTIFS('Registro de Fichas'!$D$7:$D$1200,$A12,'Registro de Fichas'!$L$7:$L$1200,"Si") -> 0 | P12: =IF($C12=0,"",IF($C12<Parametros!$B$27,"EVIDENCIA INSUFICIENTE",IF(AND($D12<>"",$C12<$D12*Parametros!$B$28),"BAJO % MUESTREO",IF($J12<Parametros!$B$31,"POCOS EVALUADORES","VALIDA"))))
B13: =IFERROR(INDEX('Registro de Fichas'!$E$7:$E$1200,MATCH($A13,'Registro de Fichas'!$D$7:$D$1200,0)),"") | C13: =COUNTIF('Registro de Fichas'!$D$7:$D$1200,$A13) -> 0 | E13: =IFERROR(AVERAGEIF('Registro de Fichas'!$D$7:$D$1200,$A13,'Registro de Fichas'!$G$7:$G$1200),"") | F13: =IFERROR(AVERAGEIF('Registro de Fichas'!$D$7:$D$1200,$A13,'Registro de Fichas'!$H$7:$H$1200),"") | G13: =IFERROR(AVERAGEIF('Registro de Fichas'!$D$7:$D$1200,$A13,'Registro de Fichas'!$I$7:$I$1200),"") | H13: =IFERROR(AVERAGEIF('Registro de Fichas'!$D$7:$D$1200,$A13,'Registro de Fichas'!$J$7:$J$1200),"") | I13: =IF($C13=0,"",IF($C13>=Parametros!$B$27,"OK","FALTAN "&(Parametros!$B$27-$C13))) | J13: =IF($C13=0,"",SUMIF('Registro de Fichas'!$D$7:$D$1200,$A13,'Registro de Fichas'!$M$7:$M$1200)) | K13: =COUNTIFS('Registro de Fichas'!$D$7:$D$1200,$A13,'Registro de Fichas'!$K$7:$K$1200,"Contenedores") -> 0 | L13: =COUNTIFS('Registro de Fichas'!$D$7:$D$1200,$A13,'Registro de Fichas'!$K$7:$K$1200,"Granel solido") -> 0 | M13: =COUNTIFS('Registro de Fichas'!$D$7:$D$1200,$A13,'Registro de Fichas'!$K$7:$K$1200,"Carga fraccionada") -> 0 | N13: =COUNTIFS('Registro de Fichas'!$D$7:$D$1200,$A13,'Registro de Fichas'!$K$7:$K$1200,"Big bags") -> 0 | O13: =COUNTIFS('Registro de Fichas'!$D$7:$D$1200,$A13,'Registro de Fichas'!$L$7:$L$1200,"Si") -> 0 | P13: =IF($C13=0,"",IF($C13<Parametros!$B$27,"EVIDENCIA INSUFICIENTE",IF(AND($D13<>"",$C13<$D13*Parametros!$B$28),"BAJO % MUESTREO",IF($J13<Parametros!$B$31,"POCOS EVALUADORES","VALIDA"))))
B14: =IFERROR(INDEX('Registro de Fichas'!$E$7:$E$1200,MATCH($A14,'Registro de Fichas'!$D$7:$D$1200,0)),"") | C14: =COUNTIF('Registro de Fichas'!$D$7:$D$1200,$A14) -> 0 | E14: =IFERROR(AVERAGEIF('Registro de Fichas'!$D$7:$D$1200,$A14,'Registro de Fichas'!$G$7:$G$1200),"") | F14: =IFERROR(AVERAGEIF('Registro de Fichas'!$D$7:$D$1200,$A14,'Registro de Fichas'!$H$7:$H$1200),"") | G14: =IFERROR(AVERAGEIF('Registro de Fichas'!$D$7:$D$1200,$A14,'Registro de Fichas'!$I$7:$I$1200),"") | H14: =IFERROR(AVERAGEIF('Registro de Fichas'!$D$7:$D$1200,$A14,'Registro de Fichas'!$J$7:$J$1200),"") | I14: =IF($C14=0,"",IF($C14>=Parametros!$B$27,"OK","FALTAN "&(Parametros!$B$27-$C14))) | J14: =IF($C14=0,"",SUMIF('Registro de Fichas'!$D$7:$D$1200,$A14,'Registro de Fichas'!$M$7:$M$1200)) | K14: =COUNTIFS('Registro de Fichas'!$D$7:$D$1200,$A14,'Registro de Fichas'!$K$7:$K$1200,"Contenedores") -> 0 | L14: =COUNTIFS('Registro de Fichas'!$D$7:$D$1200,$A14,'Registro de Fichas'!$K$7:$K$1200,"Granel solido") -> 0 | M14: =COUNTIFS('Registro de Fichas'!$D$7:$D$1200,$A14,'Registro de Fichas'!$K$7:$K$1200,"Carga fraccionada") -> 0 | N14: =COUNTIFS('Registro de Fichas'!$D$7:$D$1200,$A14,'Registro de Fichas'!$K$7:$K$1200,"Big bags") -> 0 | O14: =COUNTIFS('Registro de Fichas'!$D$7:$D$1200,$A14,'Registro de Fichas'!$L$7:$L$1200,"Si") -> 0 | P14: =IF($C14=0,"",IF($C14<Parametros!$B$27,"EVIDENCIA INSUFICIENTE",IF(AND($D14<>"",$C14<$D14*Parametros!$B$28),"BAJO % MUESTREO",IF($J14<Parametros!$B$31,"POCOS EVALUADORES","VALIDA"))))
B15: =IFERROR(INDEX('Registro de Fichas'!$E$7:$E$1200,MATCH($A15,'Registro de Fichas'!$D$7:$D$1200,0)),"") | C15: =COUNTIF('Registro de Fichas'!$D$7:$D$1200,$A15) -> 0 | E15: =IFERROR(AVERAGEIF('Registro de Fichas'!$D$7:$D$1200,$A15,'Registro de Fichas'!$G$7:$G$1200),"") | F15: =IFERROR(AVERAGEIF('Registro de Fichas'!$D$7:$D$1200,$A15,'Registro de Fichas'!$H$7:$H$1200),"") | G15: =IFERROR(AVERAGEIF('Registro de Fichas'!$D$7:$D$1200,$A15,'Registro de Fichas'!$I$7:$I$1200),"") | H15: =IFERROR(AVERAGEIF('Registro de Fichas'!$D$7:$D$1200,$A15,'Registro de Fichas'!$J$7:$J$1200),"") | I15: =IF($C15=0,"",IF($C15>=Parametros!$B$27,"OK","FALTAN "&(Parametros!$B$27-$C15))) | J15: =IF($C15=0,"",SUMIF('Registro de Fichas'!$D$7:$D$1200,$A15,'Registro de Fichas'!$M$7:$M$1200)) | K15: =COUNTIFS('Registro de Fichas'!$D$7:$D$1200,$A15,'Registro de Fichas'!$K$7:$K$1200,"Contenedores") -> 0 | L15: =COUNTIFS('Registro de Fichas'!$D$7:$D$1200,$A15,'Registro de Fichas'!$K$7:$K$1200,"Granel solido") -> 0 | M15: =COUNTIFS('Registro de Fichas'!$D$7:$D$1200,$A15,'Registro de Fichas'!$K$7:$K$1200,"Carga fraccionada") -> 0 | N15: =COUNTIFS('Registro de Fichas'!$D$7:$D$1200,$A15,'Registro de Fichas'!$K$7:$K$1200,"Big bags") -> 0 | O15: =COUNTIFS('Registro de Fichas'!$D$7:$D$1200,$A15,'Registro de Fichas'!$L$7:$L$1200,"Si") -> 0 | P15: =IF($C15=0,"",IF($C15<Parametros!$B$27,"EVIDENCIA INSUFICIENTE",IF(AND($D15<>"",$C15<$D15*Parametros!$B$28),"BAJO % MUESTREO",IF($J15<Parametros!$B$31,"POCOS EVALUADORES","VALIDA"))))
B16: =IFERROR(INDEX('Registro de Fichas'!$E$7:$E$1200,MATCH($A16,'Registro de Fichas'!$D$7:$D$1200,0)),"") | C16: =COUNTIF('Registro de Fichas'!$D$7:$D$1200,$A16) -> 0 | E16: =IFERROR(AVERAGEIF('Registro de Fichas'!$D$7:$D$1200,$A16,'Registro de Fichas'!$G$7:$G$1200),"") | F16: =IFERROR(AVERAGEIF('Registro de Fichas'!$D$7:$D$1200,$A16,'Registro de Fichas'!$H$7:$H$1200),"") | G16: =IFERROR(AVERAGEIF('Registro de Fichas'!$D$7:$D$1200,$A16,'Registro de Fichas'!$I$7:$I$1200),"") | H16: =IFERROR(AVERAGEIF('Registro de Fichas'!$D$7:$D$1200,$A16,'Registro de Fichas'!$J$7:$J$1200),"") | I16: =IF($C16=0,"",IF($C16>=Parametros!$B$27,"OK","FALTAN "&(Parametros!$B$27-$C16))) | J16: =IF($C16=0,"",SUMIF('Registro de Fichas'!$D$7:$D$1200,$A16,'Registro de Fichas'!$M$7:$M$1200)) | K16: =COUNTIFS('Registro de Fichas'!$D$7:$D$1200,$A16,'Registro de Fichas'!$K$7:$K$1200,"Contenedores") -> 0 | L16: =COUNTIFS('Registro de Fichas'!$D$7:$D$1200,$A16,'Registro de Fichas'!$K$7:$K$1200,"Granel solido") -> 0 | M16: =COUNTIFS('Registro de Fichas'!$D$7:$D$1200,$A16,'Registro de Fichas'!$K$7:$K$1200,"Carga fraccionada") -> 0 | N16: =COUNTIFS('Registro de Fichas'!$D$7:$D$1200,$A16,'Registro de Fichas'!$K$7:$K$1200,"Big bags") -> 0 | O16: =COUNTIFS('Registro de Fichas'!$D$7:$D$1200,$A16,'Registro de Fichas'!$L$7:$L$1200,"Si") -> 0 | P16: =IF($C16=0,"",IF($C16<Parametros!$B$27,"EVIDENCIA INSUFICIENTE",IF(AND($D16<>"",$C16<$D16*Parametros!$B$28),"BAJO % MUESTREO",IF($J16<Parametros!$B$31,"POCOS EVALUADORES","VALIDA"))))
B17: =IFERROR(INDEX('Registro de Fichas'!$E$7:$E$1200,MATCH($A17,'Registro de Fichas'!$D$7:$D$1200,0)),"") | C17: =COUNTIF('Registro de Fichas'!$D$7:$D$1200,$A17) -> 0 | E17: =IFERROR(AVERAGEIF('Registro de Fichas'!$D$7:$D$1200,$A17,'Registro de Fichas'!$G$7:$G$1200),"") | F17: =IFERROR(AVERAGEIF('Registro de Fichas'!$D$7:$D$1200,$A17,'Registro de Fichas'!$H$7:$H$1200),"") | G17: =IFERROR(AVERAGEIF('Registro de Fichas'!$D$7:$D$1200,$A17,'Registro de Fichas'!$I$7:$I$1200),"") | H17: =IFERROR(AVERAGEIF('Registro de Fichas'!$D$7:$D$1200,$A17,'Registro de Fichas'!$J$7:$J$1200),"") | I17: =IF($C17=0,"",IF($C17>=Parametros!$B$27,"OK","FALTAN "&(Parametros!$B$27-$C17))) | J17: =IF($C17=0,"",SUMIF('Registro de Fichas'!$D$7:$D$1200,$A17,'Registro de Fichas'!$M$7:$M$1200)) | K17: =COUNTIFS('Registro de Fichas'!$D$7:$D$1200,$A17,'Registro de Fichas'!$K$7:$K$1200,"Contenedores") -> 0 | L17: =COUNTIFS('Registro de Fichas'!$D$7:$D$1200,$A17,'Registro de Fichas'!$K$7:$K$1200,"Granel solido") -> 0 | M17: =COUNTIFS('Registro de Fichas'!$D$7:$D$1200,$A17,'Registro de Fichas'!$K$7:$K$1200,"Carga fraccionada") -> 0 | N17: =COUNTIFS('Registro de Fichas'!$D$7:$D$1200,$A17,'Registro de Fichas'!$K$7:$K$1200,"Big bags") -> 0 | O17: =COUNTIFS('Registro de Fichas'!$D$7:$D$1200,$A17,'Registro de Fichas'!$L$7:$L$1200,"Si") -> 0 | P17: =IF($C17=0,"",IF($C17<Parametros!$B$27,"EVIDENCIA INSUFICIENTE",IF(AND($D17<>"",$C17<$D17*Parametros!$B$28),"BAJO % MUESTREO",IF($J17<Parametros!$B$31,"POCOS EVALUADORES","VALIDA"))))
B18: =IFERROR(INDEX('Registro de Fichas'!$E$7:$E$1200,MATCH($A18,'Registro de Fichas'!$D$7:$D$1200,0)),"") | C18: =COUNTIF('Registro de Fichas'!$D$7:$D$1200,$A18) -> 0 | E18: =IFERROR(AVERAGEIF('Registro de Fichas'!$D$7:$D$1200,$A18,'Registro de Fichas'!$G$7:$G$1200),"") | F18: =IFERROR(AVERAGEIF('Registro de Fichas'!$D$7:$D$1200,$A18,'Registro de Fichas'!$H$7:$H$1200),"") | G18: =IFERROR(AVERAGEIF('Registro de Fichas'!$D$7:$D$1200,$A18,'Registro de Fichas'!$I$7:$I$1200),"") | H18: =IFERROR(AVERAGEIF('Registro de Fichas'!$D$7:$D$1200,$A18,'Registro de Fichas'!$J$7:$J$1200),"") | I18: =IF($C18=0,"",IF($C18>=Parametros!$B$27,"OK","FALTAN "&(Parametros!$B$27-$C18))) | J18: =IF($C18=0,"",SUMIF('Registro de Fichas'!$D$7:$D$1200,$A18,'Registro de Fichas'!$M$7:$M$1200)) | K18: =COUNTIFS('Registro de Fichas'!$D$7:$D$1200,$A18,'Registro de Fichas'!$K$7:$K$1200,"Contenedores") -> 0 | L18: =COUNTIFS('Registro de Fichas'!$D$7:$D$1200,$A18,'Registro de Fichas'!$K$7:$K$1200,"Granel solido") -> 0 | M18: =COUNTIFS('Registro de Fichas'!$D$7:$D$1200,$A18,'Registro de Fichas'!$K$7:$K$1200,"Carga fraccionada") -> 0 | N18: =COUNTIFS('Registro de Fichas'!$D$7:$D$1200,$A18,'Registro de Fichas'!$K$7:$K$1200,"Big bags") -> 0 | O18: =COUNTIFS('Registro de Fichas'!$D$7:$D$1200,$A18,'Registro de Fichas'!$L$7:$L$1200,"Si") -> 0 | P18: =IF($C18=0,"",IF($C18<Parametros!$B$27,"EVIDENCIA INSUFICIENTE",IF(AND($D18<>"",$C18<$D18*Parametros!$B$28),"BAJO % MUESTREO",IF($J18<Parametros!$B$31,"POCOS EVALUADORES","VALIDA"))))
B19: =IFERROR(INDEX('Registro de Fichas'!$E$7:$E$1200,MATCH($A19,'Registro de Fichas'!$D$7:$D$1200,0)),"") | C19: =COUNTIF('Registro de Fichas'!$D$7:$D$1200,$A19) -> 0 | E19: =IFERROR(AVERAGEIF('Registro de Fichas'!$D$7:$D$1200,$A19,'Registro de Fichas'!$G$7:$G$1200),"") | F19: =IFERROR(AVERAGEIF('Registro de Fichas'!$D$7:$D$1200,$A19,'Registro de Fichas'!$H$7:$H$1200),"") | G19: =IFERROR(AVERAGEIF('Registro de Fichas'!$D$7:$D$1200,$A19,'Registro de Fichas'!$I$7:$I$1200),"") | H19: =IFERROR(AVERAGEIF('Registro de Fichas'!$D$7:$D$1200,$A19,'Registro de Fichas'!$J$7:$J$1200),"") | I19: =IF($C19=0,"",IF($C19>=Parametros!$B$27,"OK","FALTAN "&(Parametros!$B$27-$C19))) | J19: =IF($C19=0,"",SUMIF('Registro de Fichas'!$D$7:$D$1200,$A19,'Registro de Fichas'!$M$7:$M$1200)) | K19: =COUNTIFS('Registro de Fichas'!$D$7:$D$1200,$A19,'Registro de Fichas'!$K$7:$K$1200,"Contenedores") -> 0 | L19: =COUNTIFS('Registro de Fichas'!$D$7:$D$1200,$A19,'Registro de Fichas'!$K$7:$K$1200,"Granel solido") -> 0 | M19: =COUNTIFS('Registro de Fichas'!$D$7:$D$1200,$A19,'Registro de Fichas'!$K$7:$K$1200,"Carga fraccionada") -> 0 | N19: =COUNTIFS('Registro de Fichas'!$D$7:$D$1200,$A19,'Registro de Fichas'!$K$7:$K$1200,"Big bags") -> 0 | O19: =COUNTIFS('Registro de Fichas'!$D$7:$D$1200,$A19,'Registro de Fichas'!$L$7:$L$1200,"Si") -> 0 | P19: =IF($C19=0,"",IF($C19<Parametros!$B$27,"EVIDENCIA INSUFICIENTE",IF(AND($D19<>"",$C19<$D19*Parametros!$B$28),"BAJO % MUESTREO",IF($J19<Parametros!$B$31,"POCOS EVALUADORES","VALIDA"))))
... B306: =IFERROR(INDEX('Registro de Fichas'!$E$7:$E$1200,MATCH($A306,'Registro de Fichas'!$D$7:$D$1200,0)),"") | C306: =COUNTIF('Registro de Fichas'!$D$7:$D$1200,$A306) -> 0 | E306: =IFERROR(AVERAGEIF('Registro de Fichas'!$D$7:$D$1200,$A306,'Registro de Fichas'!$G$7:$G$1200),"") | F306: =IFERROR(AVERAGEIF('Registro de Fichas'!$D$7:$D$1200,$A306,'Registro de Fichas'!$H$7:$H$1200),"") | G306: =IFERROR(AVERAGEIF('Registro de Fichas'!$D$7:$D$1200,$A306,'Registro de Fichas'!$I$7:$I$1200),"") | H306: =IFERROR(AVERAGEIF('Registro de Fichas'!$D$7:$D$1200,$A306,'Registro de Fichas'!$J$7:$J$1200),"") | I306: =IF($C306=0,"",IF($C306>=Parametros!$B$27,"OK","FALTAN "&(Parametros!$B$27-$C306))) | J306: =IF($C306=0,"",SUMIF('Registro de Fichas'!$D$7:$D$1200,$A306,'Registro de Fichas'!$M$7:$M$1200)) | K306: =COUNTIFS('Registro de Fichas'!$D$7:$D$1200,$A306,'Registro de Fichas'!$K$7:$K$1200,"Contenedores") -> 0 | L306: =COUNTIFS('Registro de Fichas'!$D$7:$D$1200,$A306,'Registro de Fichas'!$K$7:$K$1200,"Granel solido") -> 0 | M306: =COUNTIFS('Registro de Fichas'!$D$7:$D$1200,$A306,'Registro de Fichas'!$K$7:$K$1200,"Carga fraccionada") -> 0 | N306: =COUNTIFS('Registro de Fichas'!$D$7:$D$1200,$A306,'Registro de Fichas'!$K$7:$K$1200,"Big bags") -> 0 | O306: =COUNTIFS('Registro de Fichas'!$D$7:$D$1200,$A306,'Registro de Fichas'!$L$7:$L$1200,"Si") -> 0 | P306: =IF($C306=0,"",IF($C306<Parametros!$B$27,"EVIDENCIA INSUFICIENTE",IF(AND($D306<>"",$C306<$D306*Parametros!$B$28),"BAJO % MUESTREO",IF($J306<Parametros!$B$31,"POCOS EVALUADORES","VALIDA"))))
A308: LEYENDA DE ESTADO
A309: VALIDA | C309: Cumple el piso de fichas, el % de muestreo y la diversidad de evaluadores. Se puede evaluar.
A310: EVIDENCIA INSUFICIENTE | C310: Menos fichas que el piso minimo. No se fuerza la calificacion; se documenta.
A311: BAJO % MUESTREO | C311: Alcanza el piso pero no el % minimo de sus turnos trabajados.
A312: POCOS EVALUADORES | C312: Observado por menos supervisores que el minimo; riesgo de sesgo.
A313: Nota: 'Turnos trab.' se digita (turnos que el OPM efectivamente trabajo en el trimestre) y sirve para validar el % de muestreo. Los promedios O1-O4 ya incluyen el efecto de los eventos de seguridad, porque vienen topados desde la ficha del turno.
